Workbook

Sheet Vse Anotacije
A1: IPRF | B1: ipr001862 | C1: Membrane attack complex component/perforin/complement C9
A2: TCDB | B2: 1.C.39.9.1 | C2: MACPF homologue
A3: TCDB | B3: 1.C.97.5.1 | C3: 2 component system: The Pleurotolysin Pore-forming (Pleurotolysin) Family
A4: TCDB | B4: 1.C.39.4.1 | C4: Chain A, MACPF perforin-like protein, Plu-MACPF (structure solved to 2.0 Å resolution; Rosado et al., 2007).
A5: TCDB | B5: 1.C.97.1.2 | C5: 2 component system: The Pleurotolysin Pore-forming (Pleurotolysin) Family
A6: IPRF | B6: ipr000010 | C6: Cystatin domain
A7: IPRF | B7: ipr009014 | C7: Transketolase C-terminal/Pyruvate-ferredoxin oxidoreductase domain II
A8: IPRF | B8: ipr000679 | C8: Zinc finger, GATA-type
A9: IPRF | B9: ipr000073 | C9: Alpha/beta hydrolase fold-1
A10: IPRF | B10: ipr000639 | C10: Epoxide hydrolase-like
A11: IPRF | B11: ipr010497 | C11: Epoxide hydrolase, N-terminal
A12: IPRF | B12: ipr016292 | C12: Epoxide hydrolase
... A15: KOG | B15: KOG2565 | C15: Predicted hydrolases or acyltransferases (alpha/beta hydrolase superfamily)
A16: MERCO | B16: S33.971
A17: PFD | B17: pf01823 | C17: MAC/Perforin domain
A18: PFD | B18: pf00320 | C18: GATA zinc finger
A19: PFD | B19: pf00561 | C19: alpha/beta hydrolase fold
A20: PFD | B20: pf06441 | C20: Epoxide hydrolase N terminus
A21: IPRF | B21: ipr006073 | C21: GTP binding domain
A22: IPRF | B22: ipr006703 | C22: AIG1-type guanine nucleotide-binding (G) domain
A23: IPRF | B23: ipr005123 | C23: Oxoglutarate/iron-dependent dioxygenase domain
A24: IPRF | B24: ipr027417 | C24: P-loop containing nucleoside triphosphate hydrolase
A25: IPRF | B25: ipr002283 | C25: ni podatkov
A26: IPRF | B26: ipr026992 | C26: Non-haem dioxygenase, N-terminal domain
A27: KEGGEC | B27: 1.14.11.13 | C27: gibberellin 2beta-dioxygenase
A28: KOG | B28: KOG0143 | C28: Iron/ascorbate family oxidoreductases
... A47: IPRF | B47: ipr030379 | C47: Septin-type guanine nucleotide-binding (G) domain
A48: KOG | B48: KOG0401
A49: PFD | B49: pf00735 | C49: Septin
A50: PFD | B50: pf02854 | C50: MIF4G domain
A51: PFD | B51: pf03184 | C51: DDE superfamily endonuclease
A52: IPRF | B52: ipr002048 | C52: EF-hand domain
A53: IPRF | B53: ipr008985 | C53: Concanavalin A-like lectin/glucanases superfamily
A54: IPRF | B54: ipr009002 | C54: FMN-binding split barrel-related
A55: IPRF | B55: ipr009413 | C55: Hemolysin, aegerolysin type
A56: IPRF | B56: ipr010916 | C56: TonB box, conserved site
A57: IPRF | B57: ipr011685 | C57: LETM1-like
A58: IPRF | B58: ipr029055 | C58: Nucleophile aminohydrolases, N-terminal
A59: KEGGEC | B59: 2.7.7.6 | C59: DNA-directed RNA polymerase
A60: KOG | B60: KOG1043 | C60: Ca2+-binding transmembrane protein LETM1/MRS7
...

Sheet Upoštevane Anotacije
A1: Database | B1: Accesion Number | C1: Annotation | D1: Posikano?
A2: IPRF | B2: ipr001862 | C2: Membrane attack complex component/perforin/complement C9 | D2: da
A3: IPRF | B3: ipr020863 | C3: Membrane attack complex component/perforin domain, conserved site | D3: da
A4: IPRF | B4: ipr020864 | C4: Membrane attack complex component/perforin (MACPF) domain | D4: da
A5: PFD | B5: pf01823 | C5: MAC/Perforin domain | D5: da
A6: TCDB | B6: 1.C.39.4.1 | C6: Chain A, MACPF perforin-like protein, Plu-MACPF (structure solved to 2.0 Å resolution; Rosado et al., 2007). | D6: da
A7: TCDB | B7: 1.C.39.9.1 | C7: MACPF homologue | D7: da
A8: TCDB | B8: 1.C.97.1.1 | C8: 2 component system: The Pleurotolysin Pore-forming (Pleurotolysin) Family | D8: da
A9: TCDB | B9: 1.C.97.1.2 | C9: 2 component system: The Pleurotolysin Pore-forming (Pleurotolysin) Family | D9: da
A10: TCDB | B10: 1.C.97.2.1 | C10: Putative hemolysin of 224 aas | D10: da
A11: TCDB | B11: 1.C.97.5.1 | C11: 2 component system: The Pleurotolysin Pore-forming (Pleurotolysin) Family | D11: da
A12: IPRF | B12: ipr006703 | C12: AIG1-type guanine nucleotide-binding (G) domain | D12: ne
... A17: IPRF | B17: ipr008985 | C17: Concanavalin A-like lectin/glucanases superfamily | D17: ne
C18: "perforin" | D18: da
A19: TCDB | B19: 1.C.39.8.1 | C19: MACPF-Hemopexin protein | D19: da
A20: TCDB | B20: 1.C.39.8.2 | C20: The MACPF protein homologue with hemopexin-like C-terminal repeats | D20: da
A21: PFD | B21: pf00045 | C21: Hemopexin | D21: ne
A22: IPRF | B22: ipr000585 | C22: Hemopexin-like domain | D22: ne
A23: IPRF | B23: ipr018487 | C23: Hemopexin-like repeats | D23: ne
C24: MACPF | D24: da
C25: MACPF homologue | D25: da
C26: MAC | D26: da
C27: hemolysis | D27: da
B28: GO:0019836 | C28: symbiont-mediated hemolysis of host erythrocyte | D28: ne
C29: "Pleurotolysin B" | D29: da
C30: Pleurotolysin | D30: da
C31: priA | D31: ne

Sheet pf01823
A1: pf01823 | B1: 460 | C1: anotacije
C2: IPRF | D2: ipr000010
C3: IPRF | D3: ipr001862 | E3: Membrane attack complex component/perforin/complement C9
C4: IPRF | D4: ipr003890 | E4: MIF4G-like, type 3
C5: IPRF | D5: ipr006703 | E5: AIG1-type guanine nucleotide-binding (G) domain | F5: da
C6: IPRF | D6: ipr013320 | E6: Concanavalin A-like lectin/glucanase domain superfamily | F6: da - lektini in fruiting body aegerolysins
C7: IPRF | D7: ipr016130 | E7: Protein-tyrosine phosphatase, active site | F7: ne
C8: IPRF | D8: ipr020863 | E8: Membrane attack complex component/perforin domain, conserved site | F8: da
C9: IPRF | D9: ipr020864 | E9: Membrane attack complex component/perforin (MACPF) domain
C10: PFD | D10: pf01823 | E10: MAC/Perforin domain
C11: PFD | D11: pf04548 | E11: AIG1 family
C12: PFD | D12: pf13385 | E12: Concanavalin A-like lectin/glucanases superfamily
C13: TCDB | D13: 1.C.39.4.1 | E13: Chain A, MACPF perforin-like protein, Plu-MACPF (structure solved to 2.0 Å resolution; Rosado et al., 2007).
C14: TCDB | D14: 1.C.39.9.1 | E14: MACPF homologue
C15: TCDB | D15: 1.C.97.1.1 | E15: 2 component system: The Pleurotolysin Pore-forming (Pleurotolysin) Family | F15: pleurotolysin a in pleurotolysin b
C16: TCDB | D16: 1.C.97.1.2 | E16: 2 component system: The Pleurotolysin Pore-forming (Pleurotolysin) Family | F16: Erylysin A in Erylsin B
C17: TCDB | D17: 1.C.97.2.1 | E17: Putative hemolysin of 224 aas
C18: TCDB | D18: 1.C.97.5.1 | E18: 2 component system: The Pleurotolysin Pore-forming (Pleurotolysin) Family | F18: pleurotolysin a in pleurotolysin b

Sheet ipr001862
A1: ipr001862 | B1: 50 | D1: Annotations | E1: id
D2: IPRF | E2: ipr001862 | F2: Membrane attack complex component/perforin/complement C9
D3: TCDB | E3: 1.C.39.9.1 | F3: MACPF homologue
D4: TCDB | E4: 1.C.97.5.1 | F4: 2 component system: The Pleurotolysin Pore-forming (Pleurotolysin) Family
D5: TCDB | E5: 1.C.39.4.1 | F5: Chain A, MACPF perforin-like protein, Plu-MACPF (structure solved to 2.0 Å resolution; Rosado et al., 2007).
D6: TCDB | E6: 1.C.97.1.2 | F6: 2 component system: The Pleurotolysin Pore-forming (Pleurotolysin) Family
D9: IPRF | E9: ipr000010 | F9: Cystatin domain
D10: IPRF | E10: ipr009014 | F10: Transketolase C-terminal/Pyruvate-ferredoxin oxidoreductase domain II
D11: IPRF | E11: ipr000679 | F11: Zinc finger, GATA-type
D12: IPRF | E12: ipr000073 | F12: Alpha/beta hydrolase fold-1
D13: IPRF | E13: ipr000639 | F13: Epoxide hydrolase-like
D14: IPRF | E14: ipr010497 | F14: Epoxide hydrolase, N-terminal
D15: IPRF | E15: ipr016292 | F15: Epoxide hydrolase
... D18: KOG | E18: KOG2565 | F18: Predicted hydrolases or acyltransferases (alpha/beta hydrolase superfamily)
D19: MERCO | E19: S33.971
D20: PFD | E20: pf01823 | F20: =_xlfn.XLOOKUP(E20,'Upoštevane Anotacije'!B:B,'Upoštevane Anotacije'!C:C) -> MAC/Perforin domain
D21: PFD | E21: pf00320 | F21: GATA zinc finger
D22: PFD | E22: pf00561 | F22: alpha/beta hydrolase fold
D23: PFD | E23: pf06441 | F23: Epoxide hydrolase N terminus

Sheet ipr020863
A1: ipr020863 | B1: 6
A2: Membrane attack complex component/perforin domain, conserved site
A5: Anotations | B5: ID
A6: IPRF | B6: ipr020863 | C6: Membrane attack complex component/perforin domain, conserved site | D6: =_xlfn.XLOOKUP(B6,'Upoštevane Anotacije'!B:B,'Upoštevane Anotacije'!D:D) -> da
A7: PFD | B7: pf01823 | C7: MAC/Perforin domain | D7: =_xlfn.XLOOKUP(B7,'Upoštevane Anotacije'!B:B,'Upoštevane Anotacije'!D:D) -> da
A8: IPRF | B8: ipr020864 | C8: Membrane attack complex component/perforin (MACPF) domain | D8: =_xlfn.XLOOKUP(B8,'Upoštevane Anotacije'!B:B,'Upoštevane Anotacije'!D:D) -> da
A9: PFD | B9: pf04548 | C9: AIG1 family | D9: =_xlfn.XLOOKUP(B9,'Upoštevane Anotacije'!B:B,'Upoštevane Anotacije'!D:D) -> ne
A12: IPRF | B12: ipr006073 | C12: GTP binding domain | D12: =_xlfn.XLOOKUP(B12,'Upoštevane Anotacije'!B:B,'Upoštevane Anotacije'!D:D) -> #N/A
A13: IPRF | B13: ipr006703 | C13: AIG1-type guanine nucleotide-binding (G) domain | D13: =_xlfn.XLOOKUP(B13,'Upoštevane Anotacije'!B:B,'Upoštevane Anotacije'!D:D) -> ne
A14: IPRF | B14: ipr005123 | C14: Oxoglutarate/iron-dependent dioxygenase domain | D14: =_xlfn.XLOOKUP(B14,'Upoštevane Anotacije'!B:B,'Upoštevane Anotacije'!D:D) -> #N/A
A15: IPRF | B15: ipr027417 | C15: P-loop containing nucleoside triphosphate hydrolase | D15: =_xlfn.XLOOKUP(B15,'Upoštevane Anotacije'!B:B,'Upoštevane Anotacije'!D:D) -> #N/A
A16: IPRF | B16: ipr002283 | C16: ni podatkov | D16: =_xlfn.XLOOKUP(B16,'Upoštevane Anotacije'!B:B,'Upoštevane Anotacije'!D:D) -> #N/A
A17: IPRF | B17: ipr026992 | C17: Non-haem dioxygenase, N-terminal domain | D17: =_xlfn.XLOOKUP(B17,'Upoštevane Anotacije'!B:B,'Upoštevane Anotacije'!D:D) -> #N/A
A18: KEGGEC | B18: 1.14.11.13 | C18: gibberellin 2beta-dioxygenase | D18: =_xlfn.XLOOKUP(B18,'Upoštevane Anotacije'!B:B,'Upoštevane Anotacije'!D:D) -> #N/A
A19: KOG | B19: KOG0143 | C19: Iron/ascorbate family oxidoreductases | D19: =_xlfn.XLOOKUP(B19,'Upoštevane Anotacije'!B:B,'Upoštevane Anotacije'!D:D) -> #N/A
... A23: PFD | B23: pf14226 | C23: non-haem dioxygenase in morphine synthesis N-terminal | D23: =_xlfn.XLOOKUP(B23,'Upoštevane Anotacije'!B:B,'Upoštevane Anotacije'!D:D) -> #N/A

Sheet ipr020864
A1: ipr020864
A2: Membrane attack complex component/perforin (MACPF) domain
A3: 423 | B3: Annotations
B4: PFD | C4: pf04548 | D4: AIG1 family
B5: PFD | C5: pf13385 | D5: Concanavalin A-like lectin/glucanases superfamily
B6: TCDB | C6: 1.C.39.4.1 | D6: =_xlfn.XLOOKUP(C6,'Vse Anotacije'!B:B,'Vse Anotacije'!C:C,"") -> Chain A, MACPF perforin-like protein, Plu-MACPF (structure solved to 2.0 Å resolution; Rosado et al., 2007).
B7: TCDB | C7: 1.C.39.9.1 | D7: =_xlfn.XLOOKUP(C7,'Vse Anotacije'!B:B,'Vse Anotacije'!C:C,"") -> MACPF homologue
B8: TCDB | C8: 1.C.97.1.1 | D8: The Pleurotolysin Pore-forming (Pleurotolysin) Family
B9: TCDB | C9: 1.C.97.1.2 | D9: =_xlfn.XLOOKUP(C9,'Vse Anotacije'!B:B,'Vse Anotacije'!C:C,"") -> 2 component system: The Pleurotolysin Pore-forming (Pleurotolysin) Family
B10: TCDB | C10: 1.C.97.2.1 | D10: Putative hemolysin of 224 aas
B11: IPRF | C11: ipr020863 | D11: Membrane attack complex component/perforin domain, conserved site
B12: IPRF | C12: ipr020864 | D12: Membrane attack complex component/perforin (MACPF) domain
B13: PFD | C13: pf01823 | D13: MAC/Perforin domain
B14: IPRF | C14: ipr006703 | D14: =_xlfn.XLOOKUP(C14,'Vse Anotacije'!B:B,'Vse Anotacije'!C:C,"") -> AIG1-type guanine nucleotide-binding (G) domain
B17: IPRF | C17: ipr000225 | D17: Armadillo
B18: IPRF | C18: ipr003890 | D18: MIF4G-like, type 3
B19: IPRF | C19: ipr004875 | D19: DDE superfamily endonuclease domain
B20: IPRF | C20: ipr006073 | D20: =_xlfn.XLOOKUP(C20,'Vse Anotacije'!B:B,'Vse Anotacije'!C:C,"") -> GTP binding domain
B21: IPRF | C21: ipr006600 | D21: HTH CenpB-type DNA-binding domain
B22: IPRF | C22: ipr013320 | D22: Concanavalin A-like lectin/glucanase domain superfamily
B23: IPRF | C23: ipr016024 | D23: Armadillo-type fold
B24: IPRF | C24: ipr016130 | D24: Protein-tyrosine phosphatase, active site
B25: IPRF | C25: ipr027417 | D25: =_xlfn.XLOOKUP(C25,'Vse Anotacije'!B:B,'Vse Anotacije'!C:C,"") -> P-loop containing nucleoside triphosphate hydrolase
B26: IPRF | C26: ipr029021 | D26: Protein-tyrosine phosphatase-like
B27: IPRF | C27: ipr030379 | D27: Septin-type guanine nucleotide-binding (G) domain
B28: KOG | C28: KOG0401 | D28: =_xlfn.XLOOKUP(C28,'Vse Anotacije'!B:B,'Vse Anotacije'!C:C,"")
B29: PFD | C29: pf00735 | D29: Septin
B30: PFD | C30: pf01926 | D30: =_xlfn.XLOOKUP(C30,'Vse Anotacije'!B:B,'Vse Anotacije'!C:C,"") -> 50S ribosome-binding GTPase
B31: PFD | C31: pf02854 | D31: MIF4G domain
B32: PFD | C32: pf03184 | D32: DDE superfamily endonuclease

Sheet 1.C.39.4.1
A1: 1.C.39.4.1 | B1: Chain A, MACPF perforin-like protein, Plu-MACPF (structure solved to 2.0 Ã… resolution; Rosado et al., 2007). | C1: Annotations
A2: 85 zadetkov | C2: TCDB | D2: 1.C.39.4.1 | E2: =_xlfn.XLOOKUP(D2,'Vse Anotacije'!B:B,'Vse Anotacije'!C:C) -> Chain A, MACPF perforin-like protein, Plu-MACPF (structure solved to 2.0 Å resolution; Rosado et al., 2007).
C3: IPRF | D3: ipr020864 | E3: =_xlfn.XLOOKUP(D3,'Vse Anotacije'!B:B,'Vse Anotacije'!C:C) -> Membrane attack complex component/perforin (MACPF) domain
C4: IPRF | D4: ipr001862 | E4: =_xlfn.XLOOKUP(D4,'Vse Anotacije'!B:B,'Vse Anotacije'!C:C) -> Membrane attack complex component/perforin/complement C9
C5: PFD | D5: pf01823 | E5: =_xlfn.XLOOKUP(D5,'Vse Anotacije'!B:B,'Vse Anotacije'!C:C) -> MAC/Perforin domain

Sheet 1.C.39.9.1
A1: 1.C.39.9.1 | B1: MACPF homologue | C1: Annotations
A2: 229 | C2: IPRF | D2: ipr000010 | E2: =_xlfn.XLOOKUP(D2,'Vse Anotacije'!B:B,'Vse Anotacije'!C:C) -> Cystatin domain
C3: IPRF | D3: ipr001862 | E3: =_xlfn.XLOOKUP(D3,'Vse Anotacije'!B:B,'Vse Anotacije'!C:C) -> Membrane attack complex component/perforin/complement C9
C4: IPRF | D4: ipr009014 | E4: =_xlfn.XLOOKUP(D4,'Vse Anotacije'!B:B,'Vse Anotacije'!C:C) -> Transketolase C-terminal/Pyruvate-ferredoxin oxidoreductase domain II
C5: IPRF | D5: ipr016130 | E5: =_xlfn.XLOOKUP(D5,'Vse Anotacije'!B:B,'Vse Anotacije'!C:C) -> Protein-tyrosine phosphatase, active site
C6: IPRF | D6: ipr020864 | E6: =_xlfn.XLOOKUP(D6,'Vse Anotacije'!B:B,'Vse Anotacije'!C:C) -> Membrane attack complex component/perforin (MACPF) domain
C7: IPRF | D7: ipr029021 | E7: =_xlfn.XLOOKUP(D7,'Vse Anotacije'!B:B,'Vse Anotacije'!C:C) -> Protein-tyrosine phosphatase-like
C8: KOG | D8: KOG1922 | E8: =_xlfn.XLOOKUP(D8,'Vse Anotacije'!B:B,'Vse Anotacije'!C:C) -> Rho GTPase effector BNI1 and related formins
C9: PFD | D9: pf01823 | E9: =_xlfn.XLOOKUP(D9,'Vse Anotacije'!B:B,'Vse Anotacije'!C:C) -> MAC/Perforin domain
C10: TCDB | D10: 1.C.39.9.1 | E10: =_xlfn.XLOOKUP(D10,'Vse Anotacije'!B:B,'Vse Anotacije'!C:C) -> MACPF homologue

Sheet 1.C.97.1.1
A1: 1.C.97.1.1 | B1: 2 component system: The Pleurotolysin Pore-forming (Pleurotolysin) Family | C1: Annotations
A2: 227 | C2: TCDB | D2: 1.C.97.1.1 | E2: =_xlfn.XLOOKUP(D2,'Vse Anotacije'!B:B,'Vse Anotacije'!C:C) -> The Pleurotolysin Pore-forming (Pleurotolysin) Family
C3: PFD | D3: pf01823 | E3: =_xlfn.XLOOKUP(D3,'Vse Anotacije'!B:B,'Vse Anotacije'!C:C) -> MAC/Perforin domain
C4: PFD | D4: pf06355 | E4: Aegerolysin
C5: IPRF | D5: ipr020864 | E5: =_xlfn.XLOOKUP(D5,'Vse Anotacije'!B:B,'Vse Anotacije'!C:C) -> Membrane attack complex component/perforin (MACPF) domain
C6: IPRF | D6: ipr009413 | E6: Hemolysin, aegerolysin type
C7: IPRF | D7: ipr008985 | E7: Concanavalin A-like lectin/glucanases superfamily
C10: IPRF | D10: ipr002048 | E10: EF-hand domain
C11: IPRF | D11: ipr009002 | E11: FMN-binding split barrel-related
C12: IPRF | D12: ipr010916 | E12: TonB box, conserved site
C13: IPRF | D13: ipr011685 | E13: LETM1-like
C14: IPRF | D14: ipr029055 | E14: Nucleophile aminohydrolases, N-terminal
C15: KEGGEC | D15: 2.7.7.6 | E15: DNA-directed RNA polymerase
C16: KOG | D16: KOG1043 | E16: Ca2+-binding transmembrane protein LETM1/MRS7
C17: PFD | D17: pf07766 | E17: LETM1-like, RBD
C18: TCDB | D18: 2.A.97.1.1 | E18: LETM1 and EF-hand domain-containing protein 1, mitochondrial

Sheet 1.C.97.1.2
A1: 1.C.97.1.2 | B1: Erylysin A/B pore-forming toxin (Shibata et al., 2010) | C1: Annotations
A2: 98 | C2: IPRF | D2: ipr001862 | E2: =_xlfn.XLOOKUP(D2,'Vse Anotacije'!B:B,'Vse Anotacije'!C:C) -> Membrane attack complex component/perforin/complement C9
C3: IPRF | D3: ipr009413 | E3: =_xlfn.XLOOKUP(D3,'Vse Anotacije'!B:B,'Vse Anotacije'!C:C) -> Hemolysin, aegerolysin type
C4: IPRF | D4: ipr013320 | E4: =_xlfn.XLOOKUP(D4,'Vse Anotacije'!B:B,'Vse Anotacije'!C:C) -> Concanavalin A-like lectin/glucanase domain superfamily
C5: IPRF | D5: ipr020864 | E5: =_xlfn.XLOOKUP(D5,'Vse Anotacije'!B:B,'Vse Anotacije'!C:C) -> Membrane attack complex component/perforin (MACPF) domain
C6: PFD | D6: pf01823 | E6: =_xlfn.XLOOKUP(D6,'Vse Anotacije'!B:B,'Vse Anotacije'!C:C) -> MAC/Perforin domain
C7: PFD | D7: pf06355 | E7: =_xlfn.XLOOKUP(D7,'Vse Anotacije'!B:B,'Vse Anotacije'!C:C) -> Aegerolysin
C8: TCDB | D8: 1.C.97.1.2 | E8: =_xlfn.XLOOKUP(D8,'Vse Anotacije'!B:B,'Vse Anotacije'!C:C) -> 2 component system: The Pleurotolysin Pore-forming (Pleurotolysin) Family
C12: IPRF | D12: ipr001547 | E12: Glycoside hydrolase, family 5
C13: IPRF | D13: ipr015425 | E13: Formin, FH2 domain
C14: KOG | D14: KOG1922 | E14: Rho GTPase effector BNI1 and related formins

Sheet 1.C.97.2.1
A1: 1.C.97.2.1 | B1: Putative hemolysin of 224 aas | C1: Annotations | D1: User Annotations
A2: 17 | C2: TCDB | D2: 1.C.97.2.1 | E2: =_xlfn.XLOOKUP(D2,'Vse Anotacije'!B:B,'Vse Anotacije'!C:C) -> Putative hemolysin of 224 aas
C3: IPRF | D3: ipr020864 | E3: =_xlfn.XLOOKUP(D3,'Vse Anotacije'!B:B,'Vse Anotacije'!C:C) -> Membrane attack complex component/perforin (MACPF) domain
C4: PFD | D4: pf01823 | E4: =_xlfn.XLOOKUP(D4,'Vse Anotacije'!B:B,'Vse Anotacije'!C:C) -> MAC/Perforin domain
C6: KOG | D6: KOG2992 | E6: Nucleolar GTPase/ATPase p130
C7: IPRF | D7: ipr008997 | E7: ni podatkov

Sheet 1.C.97.5.1
A1: 1.C.97.5.1 | B1: The Pleurotolysin Pore-forming (Pleurotolysin) Family | C1: Annotations | D1: User Annotations
A2: 1 | C2: TCDB | D2: 1.C.97.5.1 | E2: =_xlfn.XLOOKUP(D2,'Vse Anotacije'!B:B,'Vse Anotacije'!C:C) -> 2 component system: The Pleurotolysin Pore-forming (Pleurotolysin) Family
C3: IPRF | D3: ipr001862 | E3: =_xlfn.XLOOKUP(D3,'Vse Anotacije'!B:B,'Vse Anotacije'!C:C) -> Membrane attack complex component/perforin/complement C9
C4: PFD | D4: pf01823 | E4: =_xlfn.XLOOKUP(D4,'Vse Anotacije'!B:B,'Vse Anotacije'!C:C) -> MAC/Perforin domain

Sheet perforin
A1: perforin | B1: Annotations
A2: 614 | B2: IPRF | C2: ipr000010 | D2: =_xlfn.XLOOKUP(C2,'Vse Anotacije'!B:B,'Vse Anotacije'!C:C) -> Cystatin domain
B3: IPRF | C3: ipr000225 | D3: =_xlfn.XLOOKUP(C3,'Vse Anotacije'!B:B,'Vse Anotacije'!C:C) -> Armadillo
B4: IPRF | C4: ipr003890 | D4: =_xlfn.XLOOKUP(C4,'Vse Anotacije'!B:B,'Vse Anotacije'!C:C) -> MIF4G-like, type 3
B5: IPRF | C5: ipr004875 | D5: =_xlfn.XLOOKUP(C5,'Vse Anotacije'!B:B,'Vse Anotacije'!C:C) -> DDE superfamily endonuclease domain
B6: IPRF | C6: ipr006073 | D6: =_xlfn.XLOOKUP(C6,'Vse Anotacije'!B:B,'Vse Anotacije'!C:C) -> GTP binding domain
B7: IPRF | C7: ipr006600 | D7: =_xlfn.XLOOKUP(C7,'Vse Anotacije'!B:B,'Vse Anotacije'!C:C) -> HTH CenpB-type DNA-binding domain
B8: IPRF | C8: ipr006703 | D8: =_xlfn.XLOOKUP(C8,'Vse Anotacije'!B:B,'Vse Anotacije'!C:C) -> AIG1-type guanine nucleotide-binding (G) domain
B9: IPRF | C9: ipr009014 | D9: =_xlfn.XLOOKUP(C9,'Vse Anotacije'!B:B,'Vse Anotacije'!C:C) -> Transketolase C-terminal/Pyruvate-ferredoxin oxidoreductase domain II
B10: IPRF | C10: ipr013320 | D10: =_xlfn.XLOOKUP(C10,'Vse Anotacije'!B:B,'Vse Anotacije'!C:C) -> Concanavalin A-like lectin/glucanase domain superfamily
B11: IPRF | C11: ipr016024 | D11: =_xlfn.XLOOKUP(C11,'Vse Anotacije'!B:B,'Vse Anotacije'!C:C) -> Armadillo-type fold
B12: IPRF | C12: ipr016130 | D12: =_xlfn.XLOOKUP(C12,'Vse Anotacije'!B:B,'Vse Anotacije'!C:C) -> Protein-tyrosine phosphatase, active site
B13: IPRF | C13: ipr027417 | D13: =_xlfn.XLOOKUP(C13,'Vse Anotacije'!B:B,'Vse Anotacije'!C:C) -> P-loop containing nucleoside triphosphate hydrolase
B14: IPRF | C14: ipr029021 | D14: =_xlfn.XLOOKUP(C14,'Vse Anotacije'!B:B,'Vse Anotacije'!C:C) -> Protein-tyrosine phosphatase-like
... B25: PFD | C25: pf13385 | D25: =_xlfn.XLOOKUP(C25,'Vse Anotacije'!B:B,'Vse Anotacije'!C:C) -> Concanavalin A-like lectin/glucanases superfamily
B27: TCDB | C27: 1.C.39.8.1 | D27: MACPF-Hemopexin protein
B28: TCDB | C28: 1.C.39.8.2 | D28: The MACPF protein homologue with hemopexin-like C-terminal repeats
B29: TCDB | C29: 1.C.39.9.1 | D29: =_xlfn.XLOOKUP(C29,'Vse Anotacije'!B:B,'Vse Anotacije'!C:C) -> MACPF homologue
B30: TCDB | C30: 1.C.97.1.1 | D30: =_xlfn.XLOOKUP(C30,'Vse Anotacije'!B:B,'Vse Anotacije'!C:C) -> The Pleurotolysin Pore-forming (Pleurotolysin) Family
B31: TCDB | C31: 1.C.97.1.2 | D31: =_xlfn.XLOOKUP(C31,'Vse Anotacije'!B:B,'Vse Anotacije'!C:C) -> 2 component system: The Pleurotolysin Pore-forming (Pleurotolysin) Family
B32: TCDB | C32: 1.C.97.2.1 | D32: =_xlfn.XLOOKUP(C32,'Vse Anotacije'!B:B,'Vse Anotacije'!C:C) -> Putative hemolysin of 224 aas
B33: TCDB | C33: 1.C.97.5.1 | D33: =_xlfn.XLOOKUP(C33,'Vse Anotacije'!B:B,'Vse Anotacije'!C:C) -> 2 component system: The Pleurotolysin Pore-forming (Pleurotolysin) Family
B34: TCDB | C34: 1.C.39.4.1 | D34: =_xlfn.XLOOKUP(C34,'Vse Anotacije'!B:B,'Vse Anotacije'!C:C) -> Chain A, MACPF perforin-like protein, Plu-MACPF (structure solved to 2.0 Å resolution; Rosado et al., 2007).
B35: IPRF | C35: ipr020863 | D35: =_xlfn.XLOOKUP(C35,'Vse Anotacije'!B:B,'Vse Anotacije'!C:C) -> Membrane attack complex component/perforin domain, conserved site
B36: IPRF | C36: ipr020864 | D36: =_xlfn.XLOOKUP(C36,'Vse Anotacije'!B:B,'Vse Anotacije'!C:C) -> Membrane attack complex component/perforin (MACPF) domain
B37: IPRF | C37: ipr001862 | D37: =_xlfn.XLOOKUP(C37,'Vse Anotacije'!B:B,'Vse Anotacije'!C:C) -> Membrane attack complex component/perforin/complement C9
B38: PFD | C38: pf01823 | D38: =_xlfn.XLOOKUP(C38,'Vse Anotacije'!B:B,'Vse Anotacije'!C:C) -> MAC/Perforin domain
B39: PFD | C39: pf00045 | D39: Hemopexin
B40: IPRF | C40: ipr000585 | D40: Hemopexin-like domain
B41: IPRF | C41: ipr018487 | D41: Hemopexin-like repeats

Sheet 1.C.39.8.1
A1: 1.C.39.8.1 | B1: MACPF-Hemopexin protein | C1: Annotations
A2: 7 | C2: TCDB | D2: 1.C.39.8.1 | E2: =_xlfn.XLOOKUP(D2,'Vse Anotacije'!B:B,'Vse Anotacije'!C:C) -> MACPF-Hemopexin protein
C3: IPRF | D3: ipr000585 | E3: =_xlfn.XLOOKUP(D3,'Vse Anotacije'!B:B,'Vse Anotacije'!C:C) -> Hemopexin-like domain
C4: MERCO | D4: M10.031 | E4: =_xlfn.XLOOKUP(D4,'Vse Anotacije'!B:B,'Vse Anotacije'!C:C) -> #N/A
C5: IPRF | D5: ipr018487 | E5: =_xlfn.XLOOKUP(D5,'Vse Anotacije'!B:B,'Vse Anotacije'!C:C) -> Hemopexin-like repeats
C6: MERCO | D6: M10.UNA | E6: =_xlfn.XLOOKUP(D6,'Vse Anotacije'!B:B,'Vse Anotacije'!C:C) -> #N/A
C7: PFD | D7: pf00045 | E7: =_xlfn.XLOOKUP(D7,'Vse Anotacije'!B:B,'Vse Anotacije'!C:C) -> Hemopexin

Sheet 1.C.39.8.2
A1: 1.C.39.8.2 | B1: The MACPF protein homologue with hemopexin-like C-terminal repeats | C1: Annotations
A2: 49 | C2: TCDB | D2: 1.C.39.8.2 | E2: =_xlfn.XLOOKUP(D2,'Vse Anotacije'!B:B,'Vse Anotacije'!C:C) -> The MACPF protein homologue with hemopexin-like C-terminal repeats
C3: IPRF | D3: ipr000585 | E3: =_xlfn.XLOOKUP(D3,'Vse Anotacije'!B:B,'Vse Anotacije'!C:C) -> Hemopexin-like domain
C4: IPRF | D4: ipr018487 | E4: =_xlfn.XLOOKUP(D4,'Vse Anotacije'!B:B,'Vse Anotacije'!C:C) -> Hemopexin-like repeats
C5: PFD | D5: pf00045 | E5: =_xlfn.XLOOKUP(D5,'Vse Anotacije'!B:B,'Vse Anotacije'!C:C) -> Hemopexin

Sheet MACPF
A1: MACPF | B1: Annotations
A2: 617 | B2: IPRF | C2: ipr000010 | D2: =_xlfn.XLOOKUP(C2,'Vse Anotacije'!B:B,'Vse Anotacije'!C:C) -> Cystatin domain
B3: IPRF | C3: ipr000033 | D3: LDLR class B repeat
B4: IPRF | C4: ipr000225 | D4: =_xlfn.XLOOKUP(C4,'Vse Anotacije'!B:B,'Vse Anotacije'!C:C) -> Armadillo
B5: IPRF | C5: ipr003890 | D5: =_xlfn.XLOOKUP(C5,'Vse Anotacije'!B:B,'Vse Anotacije'!C:C) -> MIF4G-like, type 3
B6: IPRF | C6: ipr004875 | D6: =_xlfn.XLOOKUP(C6,'Vse Anotacije'!B:B,'Vse Anotacije'!C:C) -> DDE superfamily endonuclease domain
B7: IPRF | C7: ipr006073 | D7: =_xlfn.XLOOKUP(C7,'Vse Anotacije'!B:B,'Vse Anotacije'!C:C) -> GTP binding domain
B8: IPRF | C8: ipr006600 | D8: =_xlfn.XLOOKUP(C8,'Vse Anotacije'!B:B,'Vse Anotacije'!C:C) -> HTH CenpB-type DNA-binding domain
B9: IPRF | C9: ipr006703 | D9: =_xlfn.XLOOKUP(C9,'Vse Anotacije'!B:B,'Vse Anotacije'!C:C) -> AIG1-type guanine nucleotide-binding (G) domain
B10: IPRF | C10: ipr009014 | D10: =_xlfn.XLOOKUP(C10,'Vse Anotacije'!B:B,'Vse Anotacije'!C:C) -> Transketolase C-terminal/Pyruvate-ferredoxin oxidoreductase domain II
B11: IPRF | C11: ipr013320 | D11: =_xlfn.XLOOKUP(C11,'Vse Anotacije'!B:B,'Vse Anotacije'!C:C) -> Concanavalin A-like lectin/glucanase domain superfamily
B12: IPRF | C12: ipr016024 | D12: =_xlfn.XLOOKUP(C12,'Vse Anotacije'!B:B,'Vse Anotacije'!C:C) -> Armadillo-type fold
B13: IPRF | C13: ipr016130 | D13: =_xlfn.XLOOKUP(C13,'Vse Anotacije'!B:B,'Vse Anotacije'!C:C) -> Protein-tyrosine phosphatase, active site
B14: IPRF | C14: ipr018487 | D14: =_xlfn.XLOOKUP(C14,'Vse Anotacije'!B:B,'Vse Anotacije'!C:C) -> Hemopexin-like repeats
B15: IPRF | C15: ipr027417 | D15: =_xlfn.XLOOKUP(C15,'Vse Anotacije'!B:B,'Vse Anotacije'!C:C) -> P-loop containing nucleoside triphosphate hydrolase
... B17: IPRF | C17: ipr030379 | D17: =_xlfn.XLOOKUP(C17,'Vse Anotacije'!B:B,'Vse Anotacije'!C:C) -> Septin-type guanine nucleotide-binding (G) domain
B18: KOG | C18: KOG0401 | D18: Translation initiation factor 4F, ribosome/mRNA-bridging subunit (eIF-4G)
B19: KOG | C19: KOG1215 | D19: Low-density lipoprotein receptors containing Ca2+-binding EGF-like domains
B20: KOG | C20: KOG1922 | D20: =_xlfn.XLOOKUP(C20,'Vse Anotacije'!B:B,'Vse Anotacije'!C:C) -> Rho GTPase effector BNI1 and related formins
B21: MERCO | C21: M10.031 | D21: =_xlfn.XLOOKUP(C21,'Vse Anotacije'!B:B,'Vse Anotacije'!C:C) -> #N/A
B22: MERCO | C22: M10.UNA | D22: =_xlfn.XLOOKUP(C22,'Vse Anotacije'!B:B,'Vse Anotacije'!C:C) -> #N/A
B23: PFD | C23: pf00045 | D23: =_xlfn.XLOOKUP(C23,'Vse Anotacije'!B:B,'Vse Anotacije'!C:C) -> Hemopexin
B24: PFD | C24: pf00735 | D24: =_xlfn.XLOOKUP(C24,'Vse Anotacije'!B:B,'Vse Anotacije'!C:C) -> Septin
B25: PFD | C25: pf01926 | D25: =_xlfn.XLOOKUP(C25,'Vse Anotacije'!B:B,'Vse Anotacije'!C:C) -> 50S ribosome-binding GTPase
B26: PFD | C26: pf02854 | D26: =_xlfn.XLOOKUP(C26,'Vse Anotacije'!B:B,'Vse Anotacije'!C:C) -> MIF4G domain
B27: PFD | C27: pf03184 | D27: =_xlfn.XLOOKUP(C27,'Vse Anotacije'!B:B,'Vse Anotacije'!C:C) -> DDE superfamily endonuclease
B28: PFD | C28: pf04548 | D28: =_xlfn.XLOOKUP(C28,'Vse Anotacije'!B:B,'Vse Anotacije'!C:C) -> AIG1 family
B29: PFD | C29: pf13385 | D29: =_xlfn.XLOOKUP(C29,'Vse Anotacije'!B:B,'Vse Anotacije'!C:C) -> Concanavalin A-like lectin/glucanases superfamily
B30: TCDB | C30: 9.B.87.2.1 | D30: Astrotactin-1, Astn1
B34: IPRF | C34: ipr000585 | D34: =_xlfn.XLOOKUP(C34,'Vse Anotacije'!B:B,'Vse Anotacije'!C:C) -> Hemopexin-like domain
B35: IPRF | C35: ipr001862 | D35: =_xlfn.XLOOKUP(C35,'Vse Anotacije'!B:B,'Vse Anotacije'!C:C) -> Membrane attack complex component/perforin/complement C9
B36: IPRF | C36: ipr020863 | D36: =_xlfn.XLOOKUP(C36,'Vse Anotacije'!B:B,'Vse Anotacije'!C:C) -> Membrane attack complex component/perforin domain, conserved site
B37: IPRF | C37: ipr020864 | D37: =_xlfn.XLOOKUP(C37,'Vse Anotacije'!B:B,'Vse Anotacije'!C:C) -> Membrane attack complex component/perforin (MACPF) domain
B38: TCDB | C38: 1.C.39.4.1 | D38: =_xlfn.XLOOKUP(C38,'Vse Anotacije'!B:B,'Vse Anotacije'!C:C) -> Chain A, MACPF perforin-like protein, Plu-MACPF (structure solved to 2.0 Å resolution; Rosado et al., 2007).
B39: TCDB | C39: 1.C.39.8.1 | D39: =_xlfn.XLOOKUP(C39,'Vse Anotacije'!B:B,'Vse Anotacije'!C:C) -> MACPF-Hemopexin protein
B40: TCDB | C40: 1.C.39.8.2 | D40: =_xlfn.XLOOKUP(C40,'Vse Anotacije'!B:B,'Vse Anotacije'!C:C) -> The MACPF protein homologue with hemopexin-like C-terminal repeats
B41: TCDB | C41: 1.C.39.9.1 | D41: =_xlfn.XLOOKUP(C41,'Vse Anotacije'!B:B,'Vse Anotacije'!C:C) -> MACPF homologue
B42: TCDB | C42: 1.C.97.1.1 | D42: =_xlfn.XLOOKUP(C42,'Vse Anotacije'!B:B,'Vse Anotacije'!C:C) -> The Pleurotolysin Pore-forming (Pleurotolysin) Family
B43: TCDB | C43: 1.C.97.1.2 | D43: =_xlfn.XLOOKUP(C43,'Vse Anotacije'!B:B,'Vse Anotacije'!C:C) -> 2 component system: The Pleurotolysin Pore-forming (Pleurotolysin) Family
B44: TCDB | C44: 1.C.97.2.1 | D44: =_xlfn.XLOOKUP(C44,'Vse Anotacije'!B:B,'Vse Anotacije'!C:C) -> Putative hemolysin of 224 aas
...

Sheet MACPF Homologue
A1: MACPF homologue | C1: Annotations
A2: 278 | C2: IPRF | D2: ipr000010 | E2: =_xlfn.XLOOKUP('MACPF Homologue'!D2,'Vse Anotacije'!B:B,'Vse Anotacije'!C:C) -> Cystatin domain
C3: IPRF | D3: ipr000585 | E3: =_xlfn.XLOOKUP('MACPF Homologue'!D3,'Vse Anotacije'!B:B,'Vse Anotacije'!C:C) -> Hemopexin-like domain
C4: IPRF | D4: ipr001862 | E4: =_xlfn.XLOOKUP('MACPF Homologue'!D4,'Vse Anotacije'!B:B,'Vse Anotacije'!C:C) -> Membrane attack complex component/perforin/complement C9
C5: IPRF | D5: ipr009014 | E5: =_xlfn.XLOOKUP('MACPF Homologue'!D5,'Vse Anotacije'!B:B,'Vse Anotacije'!C:C) -> Transketolase C-terminal/Pyruvate-ferredoxin oxidoreductase domain II
C6: IPRF | D6: ipr016130 | E6: =_xlfn.XLOOKUP('MACPF Homologue'!D6,'Vse Anotacije'!B:B,'Vse Anotacije'!C:C) -> Protein-tyrosine phosphatase, active site
C7: IPRF | D7: ipr018487 | E7: =_xlfn.XLOOKUP('MACPF Homologue'!D7,'Vse Anotacije'!B:B,'Vse Anotacije'!C:C) -> Hemopexin-like repeats
C8: IPRF | D8: ipr020864 | E8: =_xlfn.XLOOKUP('MACPF Homologue'!D8,'Vse Anotacije'!B:B,'Vse Anotacije'!C:C) -> Membrane attack complex component/perforin (MACPF) domain
C9: IPRF | D9: ipr029021 | E9: =_xlfn.XLOOKUP('MACPF Homologue'!D9,'Vse Anotacije'!B:B,'Vse Anotacije'!C:C) -> Protein-tyrosine phosphatase-like
C10: KOG | D10: KOG1922 | E10: =_xlfn.XLOOKUP('MACPF Homologue'!D10,'Vse Anotacije'!B:B,'Vse Anotacije'!C:C) -> Rho GTPase effector BNI1 and related formins
C11: PFD | D11: pf00045 | E11: =_xlfn.XLOOKUP('MACPF Homologue'!D11,'Vse Anotacije'!B:B,'Vse Anotacije'!C:C) -> Hemopexin
C12: PFD | D12: pf01823 | E12: =_xlfn.XLOOKUP('MACPF Homologue'!D12,'Vse Anotacije'!B:B,'Vse Anotacije'!C:C) -> MAC/Perforin domain
C13: TCDB | D13: 1.C.39.8.2 | E13: =_xlfn.XLOOKUP('MACPF Homologue'!D13,'Vse Anotacije'!B:B,'Vse Anotacije'!C:C) -> The MACPF protein homologue with hemopexin-like C-terminal repeats
C14: TCDB | D14: 1.C.39.9.1 | E14: =_xlfn.XLOOKUP('MACPF Homologue'!D14,'Vse Anotacije'!B:B,'Vse Anotacije'!C:C) -> MACPF homologue

Sheet MAC
A1: MAC | C1: Annotations
A2: 615 | C2: IPRF | D2: ipr000010 | E2: =_xlfn.XLOOKUP(D2,'Vse Anotacije'!B:B,'Vse Anotacije'!C:C) -> Cystatin domain
C3: IPRF | D3: ipr000225 | E3: =_xlfn.XLOOKUP(D3,'Vse Anotacije'!B:B,'Vse Anotacije'!C:C) -> Armadillo
C4: IPRF | D4: ipr000504 | E4: RNA recognition motif domain
C5: IPRF | D5: ipr001451 | E5: Hexapeptide repeat
C6: IPRF | D6: ipr001862 | E6: =_xlfn.XLOOKUP(D6,'Vse Anotacije'!B:B,'Vse Anotacije'!C:C) -> Membrane attack complex component/perforin/complement C9
C7: IPRF | D7: ipr003890 | E7: =_xlfn.XLOOKUP(D7,'Vse Anotacije'!B:B,'Vse Anotacije'!C:C) -> MIF4G-like, type 3
C8: IPRF | D8: ipr004875 | E8: =_xlfn.XLOOKUP(D8,'Vse Anotacije'!B:B,'Vse Anotacije'!C:C) -> DDE superfamily endonuclease domain
C9: IPRF | D9: ipr006073 | E9: =_xlfn.XLOOKUP(D9,'Vse Anotacije'!B:B,'Vse Anotacije'!C:C) -> GTP binding domain
C10: IPRF | D10: ipr006600 | E10: =_xlfn.XLOOKUP(D10,'Vse Anotacije'!B:B,'Vse Anotacije'!C:C) -> HTH CenpB-type DNA-binding domain
C11: IPRF | D11: ipr006703 | E11: =_xlfn.XLOOKUP(D11,'Vse Anotacije'!B:B,'Vse Anotacije'!C:C) -> AIG1-type guanine nucleotide-binding (G) domain
C12: IPRF | D12: ipr007110 | E12: Immunoglobulin-like domain
C13: IPRF | D13: ipr009014 | E13: =_xlfn.XLOOKUP(D13,'Vse Anotacije'!B:B,'Vse Anotacije'!C:C) -> Transketolase C-terminal/Pyruvate-ferredoxin oxidoreductase domain II
C14: IPRF | D14: ipr011004 | E14: Trimeric LpxA-like superfamily
C15: IPRF | D15: ipr013320 | E15: =_xlfn.XLOOKUP(D15,'Vse Anotacije'!B:B,'Vse Anotacije'!C:C) -> Concanavalin A-like lectin/glucanase domain superfamily
C16: IPRF | D16: ipr016024 | E16: =_xlfn.XLOOKUP(D16,'Vse Anotacije'!B:B,'Vse Anotacije'!C:C) -> Armadillo-type fold
C17: IPRF | D17: ipr016130 | E17: =_xlfn.XLOOKUP(D17,'Vse Anotacije'!B:B,'Vse Anotacije'!C:C) -> Protein-tyrosine phosphatase, active site
C18: IPRF | D18: ipr018357 | E18: Hexapeptide transferase, conserved site
C19: IPRF | D19: ipr019183 | E19: N-alpha-acetyltransferase 25, NatB auxiliary subunit
C20: IPRF | D20: ipr020863 | E20: =_xlfn.XLOOKUP(D20,'Vse Anotacije'!B:B,'Vse Anotacije'!C:C) -> Membrane attack complex component/perforin domain, conserved site
C21: IPRF | D21: ipr020864 | E21: =_xlfn.XLOOKUP(D21,'Vse Anotacije'!B:B,'Vse Anotacije'!C:C) -> Membrane attack complex component/perforin (MACPF) domain
C22: IPRF | D22: ipr024688 | E22: Maltose/galactoside acetyltransferase domain
C23: IPRF | D23: ipr027417 | E23: =_xlfn.XLOOKUP(D23,'Vse Anotacije'!B:B,'Vse Anotacije'!C:C) -> P-loop containing nucleoside triphosphate hydrolase
C24: IPRF | D24: ipr029021 | E24: =_xlfn.XLOOKUP(D24,'Vse Anotacije'!B:B,'Vse Anotacije'!C:C) -> Protein-tyrosine phosphatase-like
C25: IPRF | D25: ipr030379 | E25: =_xlfn.XLOOKUP(D25,'Vse Anotacije'!B:B,'Vse Anotacije'!C:C) -> Septin-type guanine nucleotide-binding (G) domain
C26: KEGGEC | D26: 2.3.1.30 | E26: =_xlfn.XLOOKUP(D26,'Vse Anotacije'!B:B,'Vse Anotacije'!C:C) -> #N/A
C27: KOG | D27: KOG0401 | E27: =_xlfn.XLOOKUP(D27,'Vse Anotacije'!B:B,'Vse Anotacije'!C:C)
C28: KOG | D28: KOG2053 | E28: =_xlfn.XLOOKUP(D28,'Vse Anotacije'!B:B,'Vse Anotacije'!C:C) -> #N/A
C29: KOG | D29: KOG4750 | E29: =_xlfn.XLOOKUP(D29,'Vse Anotacije'!B:B,'Vse Anotacije'!C:C) -> #N/A
C30: PFD | D30: pf00076 | E30: RNA recognition motif
C31: PFD | D31: pf00132 | E31: Bacterial transferase hexapeptide (six repeats)
C32: PFD | D32: pf00735 | E32: =_xlfn.XLOOKUP(D32,'Vse Anotacije'!B:B,'Vse Anotacije'!C:C) -> Septin
C33: PFD | D33: pf01823 | E33: =_xlfn.XLOOKUP(D33,'Vse Anotacije'!B:B,'Vse Anotacije'!C:C) -> MAC/Perforin domain
C34: PFD | D34: pf01926 | E34: =_xlfn.XLOOKUP(D34,'Vse Anotacije'!B:B,'Vse Anotacije'!C:C) -> 50S ribosome-binding GTPase
C35: PFD | D35: pf02854 | E35: =_xlfn.XLOOKUP(D35,'Vse Anotacije'!B:B,'Vse Anotacije'!C:C) -> MIF4G domain
C36: PFD | D36: pf03184 | E36: =_xlfn.XLOOKUP(D36,'Vse Anotacije'!B:B,'Vse Anotacije'!C:C) -> DDE superfamily endonuclease
C37: PFD | D37: pf04548 | E37: =_xlfn.XLOOKUP(D37,'Vse Anotacije'!B:B,'Vse Anotacije'!C:C) -> AIG1 family
C38: PFD | D38: pf09797 | E38: N-acetyltransferase B complex (NatB) non catalytic subunit
C39: PFD | D39: pf12464 | E39: Maltose acetyltransferase hexapeptide capping motif
C40: PFD | D40: pf13385 | E40: =_xlfn.XLOOKUP(D40,'Vse Anotacije'!B:B,'Vse Anotacije'!C:C) -> Concanavalin A-like lectin/glucanases superfamily
...

Sheet hemolysis
A1: hemolysis
A2: 265

Sheet pleurotolysin B
A1: Pleurotolysin B
A2: 324

Sheet pleurotolysin
A1: pleurotolysin
A2: 367

Sheet Erylysin
A1: Erylysin
A2: 100

Sheet f
